Feature: About Sample # features/about.feature:1

  Scenario: Transaction Processing                           # features/about.feature:3
    Given Sample Database                                    # features/steps/about.py:9
    When Transactions are submitted                          # features/steps/about.py:13
    Then Enforce business policies with Logic (rules + code) # features/steps/about.py:17
      Traceback (most recent call last):
        File "/Users/val/dev/fiddle/opt_locking/OptLocking/venv/lib/python3.11/site-packages/urllib3/connection.py", line 174, in _new_conn
          conn = connection.create_connection(
                 ^^^^^^^^^^^^^^^^^^^^^^^^^^^^^
        File "/Users/val/dev/fiddle/opt_locking/OptLocking/venv/lib/python3.11/site-packages/urllib3/util/connection.py", line 95, in create_connection
          raise err
        File "/Users/val/dev/fiddle/opt_locking/OptLocking/venv/lib/python3.11/site-packages/urllib3/util/connection.py", line 85, in create_connection
          sock.connect(sa)
      ConnectionRefusedError: [Errno 61] Connection refused
      
      During handling of the above exception, another exception occurred:
      
      Traceback (most recent call last):
        File "/Users/val/dev/fiddle/opt_locking/OptLocking/venv/lib/python3.11/site-packages/urllib3/connectionpool.py", line 714, in urlopen
          httplib_response = self._make_request(
                             ^^^^^^^^^^^^^^^^^^^
        File "/Users/val/dev/fiddle/opt_locking/OptLocking/venv/lib/python3.11/site-packages/urllib3/connectionpool.py", line 415, in _make_request
          conn.request(method, url, **httplib_request_kw)
        File "/Users/val/dev/fiddle/opt_locking/OptLocking/venv/lib/python3.11/site-packages/urllib3/connection.py", line 244, in request
          super(HTTPConnection, self).request(method, url, body=body, headers=headers)
        File "/Library/Frameworks/Python.framework/Versions/3.11/lib/python3.11/http/client.py", line 1282, in request
          self._send_request(method, url, body, headers, encode_chunked)
        File "/Library/Frameworks/Python.framework/Versions/3.11/lib/python3.11/http/client.py", line 1328, in _send_request
          self.endheaders(body, encode_chunked=encode_chunked)
        File "/Library/Frameworks/Python.framework/Versions/3.11/lib/python3.11/http/client.py", line 1277, in endheaders
          self._send_output(message_body, encode_chunked=encode_chunked)
        File "/Library/Frameworks/Python.framework/Versions/3.11/lib/python3.11/http/client.py", line 1037, in _send_output
          self.send(msg)
        File "/Library/Frameworks/Python.framework/Versions/3.11/lib/python3.11/http/client.py", line 975, in send
          self.connect()
        File "/Users/val/dev/fiddle/opt_locking/OptLocking/venv/lib/python3.11/site-packages/urllib3/connection.py", line 205, in connect
          conn = self._new_conn()
                 ^^^^^^^^^^^^^^^^
        File "/Users/val/dev/fiddle/opt_locking/OptLocking/venv/lib/python3.11/site-packages/urllib3/connection.py", line 186, in _new_conn
          raise NewConnectionError(
      urllib3.exceptions.NewConnectionError: <urllib3.connection.HTTPConnection object at 0x106eddcd0>: Failed to establish a new connection: [Errno 61] Connection refused
      
      During handling of the above exception, another exception occurred:
      
      Traceback (most recent call last):
        File "/Users/val/dev/fiddle/opt_locking/OptLocking/venv/lib/python3.11/site-packages/requests/adapters.py", line 440, in send
          resp = conn.urlopen(
                 ^^^^^^^^^^^^^
        File "/Users/val/dev/fiddle/opt_locking/OptLocking/venv/lib/python3.11/site-packages/urllib3/connectionpool.py", line 798, in urlopen
          retries = retries.increment(
                    ^^^^^^^^^^^^^^^^^^
        File "/Users/val/dev/fiddle/opt_locking/OptLocking/venv/lib/python3.11/site-packages/urllib3/util/retry.py", line 592, in increment
          raise MaxRetryError(_pool, url, error or ResponseError(cause))
      urllib3.exceptions.MaxRetryError: HTTPConnectionPool(host='localhost', port=5656): Max retries exceeded with url: /server_log?msg=Rules%20Report&test=Transaction%20Processing&dir=test/api_logic_server_behave/logs/scenario_logic_logs (Caused by NewConnectionError('<urllib3.connection.HTTPConnection object at 0x106eddcd0>: Failed to establish a new connection: [Errno 61] Connection refused'))
      
      During handling of the above exception, another exception occurred:
      
      Traceback (most recent call last):
        File "/Users/val/dev/fiddle/opt_locking/OptLocking/venv/lib/python3.11/site-packages/behave/model.py", line 1329, in run
          match.run(runner.context)
        File "/Users/val/dev/fiddle/opt_locking/OptLocking/venv/lib/python3.11/site-packages/behave/matchers.py", line 98, in run
          self.func(context, *args, **kwargs)
        File "features/steps/about.py", line 20, in step_impl
          test_utils.prt(f'Rules Report', scenario)
        File "/Users/val/dev/fiddle/opt_locking/OptLocking/test/api_logic_server_behave/features/steps/test_utils.py", line 19, in prt
          r = requests.get(msg_url)
              ^^^^^^^^^^^^^^^^^^^^^
        File "/Users/val/dev/fiddle/opt_locking/OptLocking/venv/lib/python3.11/site-packages/requests/api.py", line 75, in get
          return request('get', url, params=params, **kwargs)
                 ^^^^^^^^^^^^^^^^^^^^^^^^^^^^^^^^^^^^^^^^^^^^
        File "/Users/val/dev/fiddle/opt_locking/OptLocking/venv/lib/python3.11/site-packages/requests/api.py", line 61, in request
          return session.request(method=method, url=url, **kwargs)
                 ^^^^^^^^^^^^^^^^^^^^^^^^^^^^^^^^^^^^^^^^^^^^^^^^^
        File "/Users/val/dev/fiddle/opt_locking/OptLocking/venv/lib/python3.11/site-packages/requests/sessions.py", line 529, in request
          resp = self.send(prep, **send_kwargs)
                 ^^^^^^^^^^^^^^^^^^^^^^^^^^^^^^
        File "/Users/val/dev/fiddle/opt_locking/OptLocking/venv/lib/python3.11/site-packages/requests/sessions.py", line 645, in send
          r = adapter.send(request, **kwargs)
              ^^^^^^^^^^^^^^^^^^^^^^^^^^^^^^^
        File "/Users/val/dev/fiddle/opt_locking/OptLocking/venv/lib/python3.11/site-packages/requests/adapters.py", line 519, in send
          raise ConnectionError(e, request=request)
      requests.exceptions.ConnectionError: HTTPConnectionPool(host='localhost', port=5656): Max retries exceeded with url: /server_log?msg=Rules%20Report&test=Transaction%20Processing&dir=test/api_logic_server_behave/logs/scenario_logic_logs (Caused by NewConnectionError('<urllib3.connection.HTTPConnection object at 0x106eddcd0>: Failed to establish a new connection: [Errno 61] Connection refused'))


Feature: Application Integration # features/api.feature:1

  Scenario: GET Customer          # features/api.feature:3
    Given Customer Account: VINET # features/steps/api.py:9
    When GET Orders API           # features/steps/api.py:13
      Traceback (most recent call last):
        File "/Users/val/dev/fiddle/opt_locking/OptLocking/venv/lib/python3.11/site-packages/urllib3/connection.py", line 174, in _new_conn
          conn = connection.create_connection(
                 ^^^^^^^^^^^^^^^^^^^^^^^^^^^^^
        File "/Users/val/dev/fiddle/opt_locking/OptLocking/venv/lib/python3.11/site-packages/urllib3/util/connection.py", line 95, in create_connection
          raise err
        File "/Users/val/dev/fiddle/opt_locking/OptLocking/venv/lib/python3.11/site-packages/urllib3/util/connection.py", line 85, in create_connection
          sock.connect(sa)
      ConnectionRefusedError: [Errno 61] Connection refused
      
      During handling of the above exception, another exception occurred:
      
      Traceback (most recent call last):
        File "/Users/val/dev/fiddle/opt_locking/OptLocking/venv/lib/python3.11/site-packages/urllib3/connectionpool.py", line 714, in urlopen
          httplib_response = self._make_request(
                             ^^^^^^^^^^^^^^^^^^^
        File "/Users/val/dev/fiddle/opt_locking/OptLocking/venv/lib/python3.11/site-packages/urllib3/connectionpool.py", line 415, in _make_request
          conn.request(method, url, **httplib_request_kw)
        File "/Users/val/dev/fiddle/opt_locking/OptLocking/venv/lib/python3.11/site-packages/urllib3/connection.py", line 244, in request
          super(HTTPConnection, self).request(method, url, body=body, headers=headers)
        File "/Library/Frameworks/Python.framework/Versions/3.11/lib/python3.11/http/client.py", line 1282, in request
          self._send_request(method, url, body, headers, encode_chunked)
        File "/Library/Frameworks/Python.framework/Versions/3.11/lib/python3.11/http/client.py", line 1328, in _send_request
          self.endheaders(body, encode_chunked=encode_chunked)
        File "/Library/Frameworks/Python.framework/Versions/3.11/lib/python3.11/http/client.py", line 1277, in endheaders
          self._send_output(message_body, encode_chunked=encode_chunked)
        File "/Library/Frameworks/Python.framework/Versions/3.11/lib/python3.11/http/client.py", line 1037, in _send_output
          self.send(msg)
        File "/Library/Frameworks/Python.framework/Versions/3.11/lib/python3.11/http/client.py", line 975, in send
          self.connect()
        File "/Users/val/dev/fiddle/opt_locking/OptLocking/venv/lib/python3.11/site-packages/urllib3/connection.py", line 205, in connect
          conn = self._new_conn()
                 ^^^^^^^^^^^^^^^^
        File "/Users/val/dev/fiddle/opt_locking/OptLocking/venv/lib/python3.11/site-packages/urllib3/connection.py", line 186, in _new_conn
          raise NewConnectionError(
      urllib3.exceptions.NewConnectionError: <urllib3.connection.HTTPConnection object at 0x106f7d8d0>: Failed to establish a new connection: [Errno 61] Connection refused
      
      During handling of the above exception, another exception occurred:
      
      Traceback (most recent call last):
        File "/Users/val/dev/fiddle/opt_locking/OptLocking/venv/lib/python3.11/site-packages/requests/adapters.py", line 440, in send
          resp = conn.urlopen(
                 ^^^^^^^^^^^^^
        File "/Users/val/dev/fiddle/opt_locking/OptLocking/venv/lib/python3.11/site-packages/urllib3/connectionpool.py", line 798, in urlopen
          retries = retries.increment(
                    ^^^^^^^^^^^^^^^^^^
        File "/Users/val/dev/fiddle/opt_locking/OptLocking/venv/lib/python3.11/site-packages/urllib3/util/retry.py", line 592, in increment
          raise MaxRetryError(_pool, url, error or ResponseError(cause))
      urllib3.exceptions.MaxRetryError: HTTPConnectionPool(host='localhost', port=5656): Max retries exceeded with url: /api/auth/login (Caused by NewConnectionError('<urllib3.connection.HTTPConnection object at 0x106f7d8d0>: Failed to establish a new connection: [Errno 61] Connection refused'))
      
      During handling of the above exception, another exception occurred:
      
      Traceback (most recent call last):
        File "/Users/val/dev/fiddle/opt_locking/OptLocking/venv/lib/python3.11/site-packages/behave/model.py", line 1329, in run
          match.run(runner.context)
        File "/Users/val/dev/fiddle/opt_locking/OptLocking/venv/lib/python3.11/site-packages/behave/matchers.py", line 98, in run
          self.func(context, *args, **kwargs)
        File "features/steps/api.py", line 20, in step_impl
          r = requests.get(url=get_order_uri, headers= test_utils.login())
                                                       ^^^^^^^^^^^^^^^^^^
        File "/Users/val/dev/fiddle/opt_locking/OptLocking/test/api_logic_server_behave/features/steps/test_utils.py", line 24, in login
          r = requests.post(url=post_uri, json = post_data)
              ^^^^^^^^^^^^^^^^^^^^^^^^^^^^^^^^^^^^^^^^^^^^^
        File "/Users/val/dev/fiddle/opt_locking/OptLocking/venv/lib/python3.11/site-packages/requests/api.py", line 117, in post
          return request('post', url, data=data, json=json, **kwargs)
                 ^^^^^^^^^^^^^^^^^^^^^^^^^^^^^^^^^^^^^^^^^^^^^^^^^^^^
        File "/Users/val/dev/fiddle/opt_locking/OptLocking/venv/lib/python3.11/site-packages/requests/api.py", line 61, in request
          return session.request(method=method, url=url, **kwargs)
                 ^^^^^^^^^^^^^^^^^^^^^^^^^^^^^^^^^^^^^^^^^^^^^^^^^
        File "/Users/val/dev/fiddle/opt_locking/OptLocking/venv/lib/python3.11/site-packages/requests/sessions.py", line 529, in request
          resp = self.send(prep, **send_kwargs)
                 ^^^^^^^^^^^^^^^^^^^^^^^^^^^^^^
        File "/Users/val/dev/fiddle/opt_locking/OptLocking/venv/lib/python3.11/site-packages/requests/sessions.py", line 645, in send
          r = adapter.send(request, **kwargs)
              ^^^^^^^^^^^^^^^^^^^^^^^^^^^^^^^
        File "/Users/val/dev/fiddle/opt_locking/OptLocking/venv/lib/python3.11/site-packages/requests/adapters.py", line 519, in send
          raise ConnectionError(e, request=request)
      requests.exceptions.ConnectionError: HTTPConnectionPool(host='localhost', port=5656): Max retries exceeded with url: /api/auth/login (Caused by NewConnectionError('<urllib3.connection.HTTPConnection object at 0x106f7d8d0>: Failed to establish a new connection: [Errno 61] Connection refused'))

    Then VINET retrieved          # None

  Scenario: GET Department                      # features/api.feature:9
    Given Department 2                          # features/steps/api.py:31
    When GET Department with SubDepartments API # features/steps/api.py:35
    Then SubDepartments returned                # features/steps/api.py:39
      Traceback (most recent call last):
        File "/Users/val/dev/fiddle/opt_locking/OptLocking/venv/lib/python3.11/site-packages/urllib3/connection.py", line 174, in _new_conn
          conn = connection.create_connection(
                 ^^^^^^^^^^^^^^^^^^^^^^^^^^^^^
        File "/Users/val/dev/fiddle/opt_locking/OptLocking/venv/lib/python3.11/site-packages/urllib3/util/connection.py", line 95, in create_connection
          raise err
        File "/Users/val/dev/fiddle/opt_locking/OptLocking/venv/lib/python3.11/site-packages/urllib3/util/connection.py", line 85, in create_connection
          sock.connect(sa)
      ConnectionRefusedError: [Errno 61] Connection refused
      
      During handling of the above exception, another exception occurred:
      
      Traceback (most recent call last):
        File "/Users/val/dev/fiddle/opt_locking/OptLocking/venv/lib/python3.11/site-packages/urllib3/connectionpool.py", line 714, in urlopen
          httplib_response = self._make_request(
                             ^^^^^^^^^^^^^^^^^^^
        File "/Users/val/dev/fiddle/opt_locking/OptLocking/venv/lib/python3.11/site-packages/urllib3/connectionpool.py", line 415, in _make_request
          conn.request(method, url, **httplib_request_kw)
        File "/Users/val/dev/fiddle/opt_locking/OptLocking/venv/lib/python3.11/site-packages/urllib3/connection.py", line 244, in request
          super(HTTPConnection, self).request(method, url, body=body, headers=headers)
        File "/Library/Frameworks/Python.framework/Versions/3.11/lib/python3.11/http/client.py", line 1282, in request
          self._send_request(method, url, body, headers, encode_chunked)
        File "/Library/Frameworks/Python.framework/Versions/3.11/lib/python3.11/http/client.py", line 1328, in _send_request
          self.endheaders(body, encode_chunked=encode_chunked)
        File "/Library/Frameworks/Python.framework/Versions/3.11/lib/python3.11/http/client.py", line 1277, in endheaders
          self._send_output(message_body, encode_chunked=encode_chunked)
        File "/Library/Frameworks/Python.framework/Versions/3.11/lib/python3.11/http/client.py", line 1037, in _send_output
          self.send(msg)
        File "/Library/Frameworks/Python.framework/Versions/3.11/lib/python3.11/http/client.py", line 975, in send
          self.connect()
        File "/Users/val/dev/fiddle/opt_locking/OptLocking/venv/lib/python3.11/site-packages/urllib3/connection.py", line 205, in connect
          conn = self._new_conn()
                 ^^^^^^^^^^^^^^^^
        File "/Users/val/dev/fiddle/opt_locking/OptLocking/venv/lib/python3.11/site-packages/urllib3/connection.py", line 186, in _new_conn
          raise NewConnectionError(
      urllib3.exceptions.NewConnectionError: <urllib3.connection.HTTPConnection object at 0x106f68a90>: Failed to establish a new connection: [Errno 61] Connection refused
      
      During handling of the above exception, another exception occurred:
      
      Traceback (most recent call last):
        File "/Users/val/dev/fiddle/opt_locking/OptLocking/venv/lib/python3.11/site-packages/requests/adapters.py", line 440, in send
          resp = conn.urlopen(
                 ^^^^^^^^^^^^^
        File "/Users/val/dev/fiddle/opt_locking/OptLocking/venv/lib/python3.11/site-packages/urllib3/connectionpool.py", line 798, in urlopen
          retries = retries.increment(
                    ^^^^^^^^^^^^^^^^^^
        File "/Users/val/dev/fiddle/opt_locking/OptLocking/venv/lib/python3.11/site-packages/urllib3/util/retry.py", line 592, in increment
          raise MaxRetryError(_pool, url, error or ResponseError(cause))
      urllib3.exceptions.MaxRetryError: HTTPConnectionPool(host='localhost', port=5656): Max retries exceeded with url: /api/auth/login (Caused by NewConnectionError('<urllib3.connection.HTTPConnection object at 0x106f68a90>: Failed to establish a new connection: [Errno 61] Connection refused'))
      
      During handling of the above exception, another exception occurred:
      
      Traceback (most recent call last):
        File "/Users/val/dev/fiddle/opt_locking/OptLocking/venv/lib/python3.11/site-packages/behave/model.py", line 1329, in run
          match.run(runner.context)
        File "/Users/val/dev/fiddle/opt_locking/OptLocking/venv/lib/python3.11/site-packages/behave/matchers.py", line 98, in run
          self.func(context, *args, **kwargs)
        File "features/steps/api.py", line 44, in step_impl
          r = requests.get(url=get_dept_uri, headers= test_utils.login())
                                                      ^^^^^^^^^^^^^^^^^^
        File "/Users/val/dev/fiddle/opt_locking/OptLocking/test/api_logic_server_behave/features/steps/test_utils.py", line 24, in login
          r = requests.post(url=post_uri, json = post_data)
              ^^^^^^^^^^^^^^^^^^^^^^^^^^^^^^^^^^^^^^^^^^^^^
        File "/Users/val/dev/fiddle/opt_locking/OptLocking/venv/lib/python3.11/site-packages/requests/api.py", line 117, in post
          return request('post', url, data=data, json=json, **kwargs)
                 ^^^^^^^^^^^^^^^^^^^^^^^^^^^^^^^^^^^^^^^^^^^^^^^^^^^^
        File "/Users/val/dev/fiddle/opt_locking/OptLocking/venv/lib/python3.11/site-packages/requests/api.py", line 61, in request
          return session.request(method=method, url=url, **kwargs)
                 ^^^^^^^^^^^^^^^^^^^^^^^^^^^^^^^^^^^^^^^^^^^^^^^^^
        File "/Users/val/dev/fiddle/opt_locking/OptLocking/venv/lib/python3.11/site-packages/requests/sessions.py", line 529, in request
          resp = self.send(prep, **send_kwargs)
                 ^^^^^^^^^^^^^^^^^^^^^^^^^^^^^^
        File "/Users/val/dev/fiddle/opt_locking/OptLocking/venv/lib/python3.11/site-packages/requests/sessions.py", line 645, in send
          r = adapter.send(request, **kwargs)
              ^^^^^^^^^^^^^^^^^^^^^^^^^^^^^^^
        File "/Users/val/dev/fiddle/opt_locking/OptLocking/venv/lib/python3.11/site-packages/requests/adapters.py", line 519, in send
          raise ConnectionError(e, request=request)
      requests.exceptions.ConnectionError: HTTPConnectionPool(host='localhost', port=5656): Max retries exceeded with url: /api/auth/login (Caused by NewConnectionError('<urllib3.connection.HTTPConnection object at 0x106f68a90>: Failed to establish a new connection: [Errno 61] Connection refused'))


Feature: Place Order # features/place_order.feature:1

  Scenario: Good Order Custom Service                  # features/place_order.feature:3
    Given Customer Account: ALFKI                      # features/steps/place_order.py:48
      Traceback (most recent call last):
        File "/Users/val/dev/fiddle/opt_locking/OptLocking/venv/lib/python3.11/site-packages/urllib3/connection.py", line 174, in _new_conn
          conn = connection.create_connection(
                 ^^^^^^^^^^^^^^^^^^^^^^^^^^^^^
        File "/Users/val/dev/fiddle/opt_locking/OptLocking/venv/lib/python3.11/site-packages/urllib3/util/connection.py", line 95, in create_connection
          raise err
        File "/Users/val/dev/fiddle/opt_locking/OptLocking/venv/lib/python3.11/site-packages/urllib3/util/connection.py", line 85, in create_connection
          sock.connect(sa)
      ConnectionRefusedError: [Errno 61] Connection refused
      
      During handling of the above exception, another exception occurred:
      
      Traceback (most recent call last):
        File "/Users/val/dev/fiddle/opt_locking/OptLocking/venv/lib/python3.11/site-packages/urllib3/connectionpool.py", line 714, in urlopen
          httplib_response = self._make_request(
                             ^^^^^^^^^^^^^^^^^^^
        File "/Users/val/dev/fiddle/opt_locking/OptLocking/venv/lib/python3.11/site-packages/urllib3/connectionpool.py", line 415, in _make_request
          conn.request(method, url, **httplib_request_kw)
        File "/Users/val/dev/fiddle/opt_locking/OptLocking/venv/lib/python3.11/site-packages/urllib3/connection.py", line 244, in request
          super(HTTPConnection, self).request(method, url, body=body, headers=headers)
        File "/Library/Frameworks/Python.framework/Versions/3.11/lib/python3.11/http/client.py", line 1282, in request
          self._send_request(method, url, body, headers, encode_chunked)
        File "/Library/Frameworks/Python.framework/Versions/3.11/lib/python3.11/http/client.py", line 1328, in _send_request
          self.endheaders(body, encode_chunked=encode_chunked)
        File "/Library/Frameworks/Python.framework/Versions/3.11/lib/python3.11/http/client.py", line 1277, in endheaders
          self._send_output(message_body, encode_chunked=encode_chunked)
        File "/Library/Frameworks/Python.framework/Versions/3.11/lib/python3.11/http/client.py", line 1037, in _send_output
          self.send(msg)
        File "/Library/Frameworks/Python.framework/Versions/3.11/lib/python3.11/http/client.py", line 975, in send
          self.connect()
        File "/Users/val/dev/fiddle/opt_locking/OptLocking/venv/lib/python3.11/site-packages/urllib3/connection.py", line 205, in connect
          conn = self._new_conn()
                 ^^^^^^^^^^^^^^^^
        File "/Users/val/dev/fiddle/opt_locking/OptLocking/venv/lib/python3.11/site-packages/urllib3/connection.py", line 186, in _new_conn
          raise NewConnectionError(
      urllib3.exceptions.NewConnectionError: <urllib3.connection.HTTPConnection object at 0x106f6b6d0>: Failed to establish a new connection: [Errno 61] Connection refused
      
      During handling of the above exception, another exception occurred:
      
      Traceback (most recent call last):
        File "/Users/val/dev/fiddle/opt_locking/OptLocking/venv/lib/python3.11/site-packages/requests/adapters.py", line 440, in send
          resp = conn.urlopen(
                 ^^^^^^^^^^^^^
        File "/Users/val/dev/fiddle/opt_locking/OptLocking/venv/lib/python3.11/site-packages/urllib3/connectionpool.py", line 798, in urlopen
          retries = retries.increment(
                    ^^^^^^^^^^^^^^^^^^
        File "/Users/val/dev/fiddle/opt_locking/OptLocking/venv/lib/python3.11/site-packages/urllib3/util/retry.py", line 592, in increment
          raise MaxRetryError(_pool, url, error or ResponseError(cause))
      urllib3.exceptions.MaxRetryError: HTTPConnectionPool(host='localhost', port=5656): Max retries exceeded with url: /api/auth/login (Caused by NewConnectionError('<urllib3.connection.HTTPConnection object at 0x106f6b6d0>: Failed to establish a new connection: [Errno 61] Connection refused'))
      
      During handling of the above exception, another exception occurred:
      
      Traceback (most recent call last):
        File "/Users/val/dev/fiddle/opt_locking/OptLocking/venv/lib/python3.11/site-packages/behave/model.py", line 1329, in run
          match.run(runner.context)
        File "/Users/val/dev/fiddle/opt_locking/OptLocking/venv/lib/python3.11/site-packages/behave/matchers.py", line 98, in run
          self.func(context, *args, **kwargs)
        File "features/steps/place_order.py", line 50, in step_impl
          alfki_before = get_ALFLI()
                         ^^^^^^^^^^^
        File "features/steps/place_order.py", line 24, in get_ALFLI
          header = test_utils.login()
                   ^^^^^^^^^^^^^^^^^^
        File "/Users/val/dev/fiddle/opt_locking/OptLocking/test/api_logic_server_behave/features/steps/test_utils.py", line 24, in login
          r = requests.post(url=post_uri, json = post_data)
              ^^^^^^^^^^^^^^^^^^^^^^^^^^^^^^^^^^^^^^^^^^^^^
        File "/Users/val/dev/fiddle/opt_locking/OptLocking/venv/lib/python3.11/site-packages/requests/api.py", line 117, in post
          return request('post', url, data=data, json=json, **kwargs)
                 ^^^^^^^^^^^^^^^^^^^^^^^^^^^^^^^^^^^^^^^^^^^^^^^^^^^^
        File "/Users/val/dev/fiddle/opt_locking/OptLocking/venv/lib/python3.11/site-packages/requests/api.py", line 61, in request
          return session.request(method=method, url=url, **kwargs)
                 ^^^^^^^^^^^^^^^^^^^^^^^^^^^^^^^^^^^^^^^^^^^^^^^^^
        File "/Users/val/dev/fiddle/opt_locking/OptLocking/venv/lib/python3.11/site-packages/requests/sessions.py", line 529, in request
          resp = self.send(prep, **send_kwargs)
                 ^^^^^^^^^^^^^^^^^^^^^^^^^^^^^^
        File "/Users/val/dev/fiddle/opt_locking/OptLocking/venv/lib/python3.11/site-packages/requests/sessions.py", line 645, in send
          r = adapter.send(request, **kwargs)
              ^^^^^^^^^^^^^^^^^^^^^^^^^^^^^^^
        File "/Users/val/dev/fiddle/opt_locking/OptLocking/venv/lib/python3.11/site-packages/requests/adapters.py", line 519, in send
          raise ConnectionError(e, request=request)
      requests.exceptions.ConnectionError: HTTPConnectionPool(host='localhost', port=5656): Max retries exceeded with url: /api/auth/login (Caused by NewConnectionError('<urllib3.connection.HTTPConnection object at 0x106f6b6d0>: Failed to establish a new connection: [Errno 61] Connection refused'))

    When Good Order Placed                             # None
    Then Logic adjusts Balance (demo: chain up)        # None
    Then Logic adjusts Products Reordered              # None
    Then Logic sends email to salesrep                 # None
    Then Logic adjusts aggregates down on delete order # None

  Scenario: Bad Order Custom Service          # features/place_order.feature:12
    Given Customer Account: ALFKI             # features/steps/place_order.py:48
      Traceback (most recent call last):
        File "/Users/val/dev/fiddle/opt_locking/OptLocking/venv/lib/python3.11/site-packages/urllib3/connection.py", line 174, in _new_conn
          conn = connection.create_connection(
                 ^^^^^^^^^^^^^^^^^^^^^^^^^^^^^
        File "/Users/val/dev/fiddle/opt_locking/OptLocking/venv/lib/python3.11/site-packages/urllib3/util/connection.py", line 95, in create_connection
          raise err
        File "/Users/val/dev/fiddle/opt_locking/OptLocking/venv/lib/python3.11/site-packages/urllib3/util/connection.py", line 85, in create_connection
          sock.connect(sa)
      ConnectionRefusedError: [Errno 61] Connection refused
      
      During handling of the above exception, another exception occurred:
      
      Traceback (most recent call last):
        File "/Users/val/dev/fiddle/opt_locking/OptLocking/venv/lib/python3.11/site-packages/urllib3/connectionpool.py", line 714, in urlopen
          httplib_response = self._make_request(
                             ^^^^^^^^^^^^^^^^^^^
        File "/Users/val/dev/fiddle/opt_locking/OptLocking/venv/lib/python3.11/site-packages/urllib3/connectionpool.py", line 415, in _make_request
          conn.request(method, url, **httplib_request_kw)
        File "/Users/val/dev/fiddle/opt_locking/OptLocking/venv/lib/python3.11/site-packages/urllib3/connection.py", line 244, in request
          super(HTTPConnection, self).request(method, url, body=body, headers=headers)
        File "/Library/Frameworks/Python.framework/Versions/3.11/lib/python3.11/http/client.py", line 1282, in request
          self._send_request(method, url, body, headers, encode_chunked)
        File "/Library/Frameworks/Python.framework/Versions/3.11/lib/python3.11/http/client.py", line 1328, in _send_request
          self.endheaders(body, encode_chunked=encode_chunked)
        File "/Library/Frameworks/Python.framework/Versions/3.11/lib/python3.11/http/client.py", line 1277, in endheaders
          self._send_output(message_body, encode_chunked=encode_chunked)
        File "/Library/Frameworks/Python.framework/Versions/3.11/lib/python3.11/http/client.py", line 1037, in _send_output
          self.send(msg)
        File "/Library/Frameworks/Python.framework/Versions/3.11/lib/python3.11/http/client.py", line 975, in send
          self.connect()
        File "/Users/val/dev/fiddle/opt_locking/OptLocking/venv/lib/python3.11/site-packages/urllib3/connection.py", line 205, in connect
          conn = self._new_conn()
                 ^^^^^^^^^^^^^^^^
        File "/Users/val/dev/fiddle/opt_locking/OptLocking/venv/lib/python3.11/site-packages/urllib3/connection.py", line 186, in _new_conn
          raise NewConnectionError(
      urllib3.exceptions.NewConnectionError: <urllib3.connection.HTTPConnection object at 0x106f82c90>: Failed to establish a new connection: [Errno 61] Connection refused
      
      During handling of the above exception, another exception occurred:
      
      Traceback (most recent call last):
        File "/Users/val/dev/fiddle/opt_locking/OptLocking/venv/lib/python3.11/site-packages/requests/adapters.py", line 440, in send
          resp = conn.urlopen(
                 ^^^^^^^^^^^^^
        File "/Users/val/dev/fiddle/opt_locking/OptLocking/venv/lib/python3.11/site-packages/urllib3/connectionpool.py", line 798, in urlopen
          retries = retries.increment(
                    ^^^^^^^^^^^^^^^^^^
        File "/Users/val/dev/fiddle/opt_locking/OptLocking/venv/lib/python3.11/site-packages/urllib3/util/retry.py", line 592, in increment
          raise MaxRetryError(_pool, url, error or ResponseError(cause))
      urllib3.exceptions.MaxRetryError: HTTPConnectionPool(host='localhost', port=5656): Max retries exceeded with url: /api/auth/login (Caused by NewConnectionError('<urllib3.connection.HTTPConnection object at 0x106f82c90>: Failed to establish a new connection: [Errno 61] Connection refused'))
      
      During handling of the above exception, another exception occurred:
      
      Traceback (most recent call last):
        File "/Users/val/dev/fiddle/opt_locking/OptLocking/venv/lib/python3.11/site-packages/behave/model.py", line 1329, in run
          match.run(runner.context)
        File "/Users/val/dev/fiddle/opt_locking/OptLocking/venv/lib/python3.11/site-packages/behave/matchers.py", line 98, in run
          self.func(context, *args, **kwargs)
        File "features/steps/place_order.py", line 50, in step_impl
          alfki_before = get_ALFLI()
                         ^^^^^^^^^^^
        File "features/steps/place_order.py", line 24, in get_ALFLI
          header = test_utils.login()
                   ^^^^^^^^^^^^^^^^^^
        File "/Users/val/dev/fiddle/opt_locking/OptLocking/test/api_logic_server_behave/features/steps/test_utils.py", line 24, in login
          r = requests.post(url=post_uri, json = post_data)
              ^^^^^^^^^^^^^^^^^^^^^^^^^^^^^^^^^^^^^^^^^^^^^
        File "/Users/val/dev/fiddle/opt_locking/OptLocking/venv/lib/python3.11/site-packages/requests/api.py", line 117, in post
          return request('post', url, data=data, json=json, **kwargs)
                 ^^^^^^^^^^^^^^^^^^^^^^^^^^^^^^^^^^^^^^^^^^^^^^^^^^^^
        File "/Users/val/dev/fiddle/opt_locking/OptLocking/venv/lib/python3.11/site-packages/requests/api.py", line 61, in request
          return session.request(method=method, url=url, **kwargs)
                 ^^^^^^^^^^^^^^^^^^^^^^^^^^^^^^^^^^^^^^^^^^^^^^^^^
        File "/Users/val/dev/fiddle/opt_locking/OptLocking/venv/lib/python3.11/site-packages/requests/sessions.py", line 529, in request
          resp = self.send(prep, **send_kwargs)
                 ^^^^^^^^^^^^^^^^^^^^^^^^^^^^^^
        File "/Users/val/dev/fiddle/opt_locking/OptLocking/venv/lib/python3.11/site-packages/requests/sessions.py", line 645, in send
          r = adapter.send(request, **kwargs)
              ^^^^^^^^^^^^^^^^^^^^^^^^^^^^^^^
        File "/Users/val/dev/fiddle/opt_locking/OptLocking/venv/lib/python3.11/site-packages/requests/adapters.py", line 519, in send
          raise ConnectionError(e, request=request)
      requests.exceptions.ConnectionError: HTTPConnectionPool(host='localhost', port=5656): Max retries exceeded with url: /api/auth/login (Caused by NewConnectionError('<urllib3.connection.HTTPConnection object at 0x106f82c90>: Failed to establish a new connection: [Errno 61] Connection refused'))

    When Order Placed with excessive quantity # None
    Then Rejected per Check Credit            # None

  Scenario: Alter Item Qty to exceed credit      # features/place_order.feature:18
    Given Customer Account: ALFKI                # features/steps/place_order.py:48
      Traceback (most recent call last):
        File "/Users/val/dev/fiddle/opt_locking/OptLocking/venv/lib/python3.11/site-packages/urllib3/connection.py", line 174, in _new_conn
          conn = connection.create_connection(
                 ^^^^^^^^^^^^^^^^^^^^^^^^^^^^^
        File "/Users/val/dev/fiddle/opt_locking/OptLocking/venv/lib/python3.11/site-packages/urllib3/util/connection.py", line 95, in create_connection
          raise err
        File "/Users/val/dev/fiddle/opt_locking/OptLocking/venv/lib/python3.11/site-packages/urllib3/util/connection.py", line 85, in create_connection
          sock.connect(sa)
      ConnectionRefusedError: [Errno 61] Connection refused
      
      During handling of the above exception, another exception occurred:
      
      Traceback (most recent call last):
        File "/Users/val/dev/fiddle/opt_locking/OptLocking/venv/lib/python3.11/site-packages/urllib3/connectionpool.py", line 714, in urlopen
          httplib_response = self._make_request(
                             ^^^^^^^^^^^^^^^^^^^
        File "/Users/val/dev/fiddle/opt_locking/OptLocking/venv/lib/python3.11/site-packages/urllib3/connectionpool.py", line 415, in _make_request
          conn.request(method, url, **httplib_request_kw)
        File "/Users/val/dev/fiddle/opt_locking/OptLocking/venv/lib/python3.11/site-packages/urllib3/connection.py", line 244, in request
          super(HTTPConnection, self).request(method, url, body=body, headers=headers)
        File "/Library/Frameworks/Python.framework/Versions/3.11/lib/python3.11/http/client.py", line 1282, in request
          self._send_request(method, url, body, headers, encode_chunked)
        File "/Library/Frameworks/Python.framework/Versions/3.11/lib/python3.11/http/client.py", line 1328, in _send_request
          self.endheaders(body, encode_chunked=encode_chunked)
        File "/Library/Frameworks/Python.framework/Versions/3.11/lib/python3.11/http/client.py", line 1277, in endheaders
          self._send_output(message_body, encode_chunked=encode_chunked)
        File "/Library/Frameworks/Python.framework/Versions/3.11/lib/python3.11/http/client.py", line 1037, in _send_output
          self.send(msg)
        File "/Library/Frameworks/Python.framework/Versions/3.11/lib/python3.11/http/client.py", line 975, in send
          self.connect()
        File "/Users/val/dev/fiddle/opt_locking/OptLocking/venv/lib/python3.11/site-packages/urllib3/connection.py", line 205, in connect
          conn = self._new_conn()
                 ^^^^^^^^^^^^^^^^
        File "/Users/val/dev/fiddle/opt_locking/OptLocking/venv/lib/python3.11/site-packages/urllib3/connection.py", line 186, in _new_conn
          raise NewConnectionError(
      urllib3.exceptions.NewConnectionError: <urllib3.connection.HTTPConnection object at 0x106f8d990>: Failed to establish a new connection: [Errno 61] Connection refused
      
      During handling of the above exception, another exception occurred:
      
      Traceback (most recent call last):
        File "/Users/val/dev/fiddle/opt_locking/OptLocking/venv/lib/python3.11/site-packages/requests/adapters.py", line 440, in send
          resp = conn.urlopen(
                 ^^^^^^^^^^^^^
        File "/Users/val/dev/fiddle/opt_locking/OptLocking/venv/lib/python3.11/site-packages/urllib3/connectionpool.py", line 798, in urlopen
          retries = retries.increment(
                    ^^^^^^^^^^^^^^^^^^
        File "/Users/val/dev/fiddle/opt_locking/OptLocking/venv/lib/python3.11/site-packages/urllib3/util/retry.py", line 592, in increment
          raise MaxRetryError(_pool, url, error or ResponseError(cause))
      urllib3.exceptions.MaxRetryError: HTTPConnectionPool(host='localhost', port=5656): Max retries exceeded with url: /api/auth/login (Caused by NewConnectionError('<urllib3.connection.HTTPConnection object at 0x106f8d990>: Failed to establish a new connection: [Errno 61] Connection refused'))
      
      During handling of the above exception, another exception occurred:
      
      Traceback (most recent call last):
        File "/Users/val/dev/fiddle/opt_locking/OptLocking/venv/lib/python3.11/site-packages/behave/model.py", line 1329, in run
          match.run(runner.context)
        File "/Users/val/dev/fiddle/opt_locking/OptLocking/venv/lib/python3.11/site-packages/behave/matchers.py", line 98, in run
          self.func(context, *args, **kwargs)
        File "features/steps/place_order.py", line 50, in step_impl
          alfki_before = get_ALFLI()
                         ^^^^^^^^^^^
        File "features/steps/place_order.py", line 24, in get_ALFLI
          header = test_utils.login()
                   ^^^^^^^^^^^^^^^^^^
        File "/Users/val/dev/fiddle/opt_locking/OptLocking/test/api_logic_server_behave/features/steps/test_utils.py", line 24, in login
          r = requests.post(url=post_uri, json = post_data)
              ^^^^^^^^^^^^^^^^^^^^^^^^^^^^^^^^^^^^^^^^^^^^^
        File "/Users/val/dev/fiddle/opt_locking/OptLocking/venv/lib/python3.11/site-packages/requests/api.py", line 117, in post
          return request('post', url, data=data, json=json, **kwargs)
                 ^^^^^^^^^^^^^^^^^^^^^^^^^^^^^^^^^^^^^^^^^^^^^^^^^^^^
        File "/Users/val/dev/fiddle/opt_locking/OptLocking/venv/lib/python3.11/site-packages/requests/api.py", line 61, in request
          return session.request(method=method, url=url, **kwargs)
                 ^^^^^^^^^^^^^^^^^^^^^^^^^^^^^^^^^^^^^^^^^^^^^^^^^
        File "/Users/val/dev/fiddle/opt_locking/OptLocking/venv/lib/python3.11/site-packages/requests/sessions.py", line 529, in request
          resp = self.send(prep, **send_kwargs)
                 ^^^^^^^^^^^^^^^^^^^^^^^^^^^^^^
        File "/Users/val/dev/fiddle/opt_locking/OptLocking/venv/lib/python3.11/site-packages/requests/sessions.py", line 645, in send
          r = adapter.send(request, **kwargs)
              ^^^^^^^^^^^^^^^^^^^^^^^^^^^^^^^
        File "/Users/val/dev/fiddle/opt_locking/OptLocking/venv/lib/python3.11/site-packages/requests/adapters.py", line 519, in send
          raise ConnectionError(e, request=request)
      requests.exceptions.ConnectionError: HTTPConnectionPool(host='localhost', port=5656): Max retries exceeded with url: /api/auth/login (Caused by NewConnectionError('<urllib3.connection.HTTPConnection object at 0x106f8d990>: Failed to establish a new connection: [Errno 61] Connection refused'))

    When Order Detail Quantity altered very high # None
    Then Rejected per Check Credit               # None

  Scenario: Alter Required Date - adjust logic pruned  # features/place_order.feature:24
    Given Customer Account: ALFKI                      # features/steps/place_order.py:48
      Traceback (most recent call last):
        File "/Users/val/dev/fiddle/opt_locking/OptLocking/venv/lib/python3.11/site-packages/urllib3/connection.py", line 174, in _new_conn
          conn = connection.create_connection(
                 ^^^^^^^^^^^^^^^^^^^^^^^^^^^^^
        File "/Users/val/dev/fiddle/opt_locking/OptLocking/venv/lib/python3.11/site-packages/urllib3/util/connection.py", line 95, in create_connection
          raise err
        File "/Users/val/dev/fiddle/opt_locking/OptLocking/venv/lib/python3.11/site-packages/urllib3/util/connection.py", line 85, in create_connection
          sock.connect(sa)
      ConnectionRefusedError: [Errno 61] Connection refused
      
      During handling of the above exception, another exception occurred:
      
      Traceback (most recent call last):
        File "/Users/val/dev/fiddle/opt_locking/OptLocking/venv/lib/python3.11/site-packages/urllib3/connectionpool.py", line 714, in urlopen
          httplib_response = self._make_request(
                             ^^^^^^^^^^^^^^^^^^^
        File "/Users/val/dev/fiddle/opt_locking/OptLocking/venv/lib/python3.11/site-packages/urllib3/connectionpool.py", line 415, in _make_request
          conn.request(method, url, **httplib_request_kw)
        File "/Users/val/dev/fiddle/opt_locking/OptLocking/venv/lib/python3.11/site-packages/urllib3/connection.py", line 244, in request
          super(HTTPConnection, self).request(method, url, body=body, headers=headers)
        File "/Library/Frameworks/Python.framework/Versions/3.11/lib/python3.11/http/client.py", line 1282, in request
          self._send_request(method, url, body, headers, encode_chunked)
        File "/Library/Frameworks/Python.framework/Versions/3.11/lib/python3.11/http/client.py", line 1328, in _send_request
          self.endheaders(body, encode_chunked=encode_chunked)
        File "/Library/Frameworks/Python.framework/Versions/3.11/lib/python3.11/http/client.py", line 1277, in endheaders
          self._send_output(message_body, encode_chunked=encode_chunked)
        File "/Library/Frameworks/Python.framework/Versions/3.11/lib/python3.11/http/client.py", line 1037, in _send_output
          self.send(msg)
        File "/Library/Frameworks/Python.framework/Versions/3.11/lib/python3.11/http/client.py", line 975, in send
          self.connect()
        File "/Users/val/dev/fiddle/opt_locking/OptLocking/venv/lib/python3.11/site-packages/urllib3/connection.py", line 205, in connect
          conn = self._new_conn()
                 ^^^^^^^^^^^^^^^^
        File "/Users/val/dev/fiddle/opt_locking/OptLocking/venv/lib/python3.11/site-packages/urllib3/connection.py", line 186, in _new_conn
          raise NewConnectionError(
      urllib3.exceptions.NewConnectionError: <urllib3.connection.HTTPConnection object at 0x106f947d0>: Failed to establish a new connection: [Errno 61] Connection refused
      
      During handling of the above exception, another exception occurred:
      
      Traceback (most recent call last):
        File "/Users/val/dev/fiddle/opt_locking/OptLocking/venv/lib/python3.11/site-packages/requests/adapters.py", line 440, in send
          resp = conn.urlopen(
                 ^^^^^^^^^^^^^
        File "/Users/val/dev/fiddle/opt_locking/OptLocking/venv/lib/python3.11/site-packages/urllib3/connectionpool.py", line 798, in urlopen
          retries = retries.increment(
                    ^^^^^^^^^^^^^^^^^^
        File "/Users/val/dev/fiddle/opt_locking/OptLocking/venv/lib/python3.11/site-packages/urllib3/util/retry.py", line 592, in increment
          raise MaxRetryError(_pool, url, error or ResponseError(cause))
      urllib3.exceptions.MaxRetryError: HTTPConnectionPool(host='localhost', port=5656): Max retries exceeded with url: /api/auth/login (Caused by NewConnectionError('<urllib3.connection.HTTPConnection object at 0x106f947d0>: Failed to establish a new connection: [Errno 61] Connection refused'))
      
      During handling of the above exception, another exception occurred:
      
      Traceback (most recent call last):
        File "/Users/val/dev/fiddle/opt_locking/OptLocking/venv/lib/python3.11/site-packages/behave/model.py", line 1329, in run
          match.run(runner.context)
        File "/Users/val/dev/fiddle/opt_locking/OptLocking/venv/lib/python3.11/site-packages/behave/matchers.py", line 98, in run
          self.func(context, *args, **kwargs)
        File "features/steps/place_order.py", line 50, in step_impl
          alfki_before = get_ALFLI()
                         ^^^^^^^^^^^
        File "features/steps/place_order.py", line 24, in get_ALFLI
          header = test_utils.login()
                   ^^^^^^^^^^^^^^^^^^
        File "/Users/val/dev/fiddle/opt_locking/OptLocking/test/api_logic_server_behave/features/steps/test_utils.py", line 24, in login
          r = requests.post(url=post_uri, json = post_data)
              ^^^^^^^^^^^^^^^^^^^^^^^^^^^^^^^^^^^^^^^^^^^^^
        File "/Users/val/dev/fiddle/opt_locking/OptLocking/venv/lib/python3.11/site-packages/requests/api.py", line 117, in post
          return request('post', url, data=data, json=json, **kwargs)
                 ^^^^^^^^^^^^^^^^^^^^^^^^^^^^^^^^^^^^^^^^^^^^^^^^^^^^
        File "/Users/val/dev/fiddle/opt_locking/OptLocking/venv/lib/python3.11/site-packages/requests/api.py", line 61, in request
          return session.request(method=method, url=url, **kwargs)
                 ^^^^^^^^^^^^^^^^^^^^^^^^^^^^^^^^^^^^^^^^^^^^^^^^^
        File "/Users/val/dev/fiddle/opt_locking/OptLocking/venv/lib/python3.11/site-packages/requests/sessions.py", line 529, in request
          resp = self.send(prep, **send_kwargs)
                 ^^^^^^^^^^^^^^^^^^^^^^^^^^^^^^
        File "/Users/val/dev/fiddle/opt_locking/OptLocking/venv/lib/python3.11/site-packages/requests/sessions.py", line 645, in send
          r = adapter.send(request, **kwargs)
              ^^^^^^^^^^^^^^^^^^^^^^^^^^^^^^^
        File "/Users/val/dev/fiddle/opt_locking/OptLocking/venv/lib/python3.11/site-packages/requests/adapters.py", line 519, in send
          raise ConnectionError(e, request=request)
      requests.exceptions.ConnectionError: HTTPConnectionPool(host='localhost', port=5656): Max retries exceeded with url: /api/auth/login (Caused by NewConnectionError('<urllib3.connection.HTTPConnection object at 0x106f947d0>: Failed to establish a new connection: [Errno 61] Connection refused'))

    When Order RequiredDate altered (2013-10-13)       # None
    Then Balance not adjusted                          # None

  Scenario: Set Shipped - adjust logic reuse    # features/place_order.feature:30
    Given Customer Account: ALFKI               # features/steps/place_order.py:48
      Traceback (most recent call last):
        File "/Users/val/dev/fiddle/opt_locking/OptLocking/venv/lib/python3.11/site-packages/urllib3/connection.py", line 174, in _new_conn
          conn = connection.create_connection(
                 ^^^^^^^^^^^^^^^^^^^^^^^^^^^^^
        File "/Users/val/dev/fiddle/opt_locking/OptLocking/venv/lib/python3.11/site-packages/urllib3/util/connection.py", line 95, in create_connection
          raise err
        File "/Users/val/dev/fiddle/opt_locking/OptLocking/venv/lib/python3.11/site-packages/urllib3/util/connection.py", line 85, in create_connection
          sock.connect(sa)
      ConnectionRefusedError: [Errno 61] Connection refused
      
      During handling of the above exception, another exception occurred:
      
      Traceback (most recent call last):
        File "/Users/val/dev/fiddle/opt_locking/OptLocking/venv/lib/python3.11/site-packages/urllib3/connectionpool.py", line 714, in urlopen
          httplib_response = self._make_request(
                             ^^^^^^^^^^^^^^^^^^^
        File "/Users/val/dev/fiddle/opt_locking/OptLocking/venv/lib/python3.11/site-packages/urllib3/connectionpool.py", line 415, in _make_request
          conn.request(method, url, **httplib_request_kw)
        File "/Users/val/dev/fiddle/opt_locking/OptLocking/venv/lib/python3.11/site-packages/urllib3/connection.py", line 244, in request
          super(HTTPConnection, self).request(method, url, body=body, headers=headers)
        File "/Library/Frameworks/Python.framework/Versions/3.11/lib/python3.11/http/client.py", line 1282, in request
          self._send_request(method, url, body, headers, encode_chunked)
        File "/Library/Frameworks/Python.framework/Versions/3.11/lib/python3.11/http/client.py", line 1328, in _send_request
          self.endheaders(body, encode_chunked=encode_chunked)
        File "/Library/Frameworks/Python.framework/Versions/3.11/lib/python3.11/http/client.py", line 1277, in endheaders
          self._send_output(message_body, encode_chunked=encode_chunked)
        File "/Library/Frameworks/Python.framework/Versions/3.11/lib/python3.11/http/client.py", line 1037, in _send_output
          self.send(msg)
        File "/Library/Frameworks/Python.framework/Versions/3.11/lib/python3.11/http/client.py", line 975, in send
          self.connect()
        File "/Users/val/dev/fiddle/opt_locking/OptLocking/venv/lib/python3.11/site-packages/urllib3/connection.py", line 205, in connect
          conn = self._new_conn()
                 ^^^^^^^^^^^^^^^^
        File "/Users/val/dev/fiddle/opt_locking/OptLocking/venv/lib/python3.11/site-packages/urllib3/connection.py", line 186, in _new_conn
          raise NewConnectionError(
      urllib3.exceptions.NewConnectionError: <urllib3.connection.HTTPConnection object at 0x106f97890>: Failed to establish a new connection: [Errno 61] Connection refused
      
      During handling of the above exception, another exception occurred:
      
      Traceback (most recent call last):
        File "/Users/val/dev/fiddle/opt_locking/OptLocking/venv/lib/python3.11/site-packages/requests/adapters.py", line 440, in send
          resp = conn.urlopen(
                 ^^^^^^^^^^^^^
        File "/Users/val/dev/fiddle/opt_locking/OptLocking/venv/lib/python3.11/site-packages/urllib3/connectionpool.py", line 798, in urlopen
          retries = retries.increment(
                    ^^^^^^^^^^^^^^^^^^
        File "/Users/val/dev/fiddle/opt_locking/OptLocking/venv/lib/python3.11/site-packages/urllib3/util/retry.py", line 592, in increment
          raise MaxRetryError(_pool, url, error or ResponseError(cause))
      urllib3.exceptions.MaxRetryError: HTTPConnectionPool(host='localhost', port=5656): Max retries exceeded with url: /api/auth/login (Caused by NewConnectionError('<urllib3.connection.HTTPConnection object at 0x106f97890>: Failed to establish a new connection: [Errno 61] Connection refused'))
      
      During handling of the above exception, another exception occurred:
      
      Traceback (most recent call last):
        File "/Users/val/dev/fiddle/opt_locking/OptLocking/venv/lib/python3.11/site-packages/behave/model.py", line 1329, in run
          match.run(runner.context)
        File "/Users/val/dev/fiddle/opt_locking/OptLocking/venv/lib/python3.11/site-packages/behave/matchers.py", line 98, in run
          self.func(context, *args, **kwargs)
        File "features/steps/place_order.py", line 50, in step_impl
          alfki_before = get_ALFLI()
                         ^^^^^^^^^^^
        File "features/steps/place_order.py", line 24, in get_ALFLI
          header = test_utils.login()
                   ^^^^^^^^^^^^^^^^^^
        File "/Users/val/dev/fiddle/opt_locking/OptLocking/test/api_logic_server_behave/features/steps/test_utils.py", line 24, in login
          r = requests.post(url=post_uri, json = post_data)
              ^^^^^^^^^^^^^^^^^^^^^^^^^^^^^^^^^^^^^^^^^^^^^
        File "/Users/val/dev/fiddle/opt_locking/OptLocking/venv/lib/python3.11/site-packages/requests/api.py", line 117, in post
          return request('post', url, data=data, json=json, **kwargs)
                 ^^^^^^^^^^^^^^^^^^^^^^^^^^^^^^^^^^^^^^^^^^^^^^^^^^^^
        File "/Users/val/dev/fiddle/opt_locking/OptLocking/venv/lib/python3.11/site-packages/requests/api.py", line 61, in request
          return session.request(method=method, url=url, **kwargs)
                 ^^^^^^^^^^^^^^^^^^^^^^^^^^^^^^^^^^^^^^^^^^^^^^^^^
        File "/Users/val/dev/fiddle/opt_locking/OptLocking/venv/lib/python3.11/site-packages/requests/sessions.py", line 529, in request
          resp = self.send(prep, **send_kwargs)
                 ^^^^^^^^^^^^^^^^^^^^^^^^^^^^^^
        File "/Users/val/dev/fiddle/opt_locking/OptLocking/venv/lib/python3.11/site-packages/requests/sessions.py", line 645, in send
          r = adapter.send(request, **kwargs)
              ^^^^^^^^^^^^^^^^^^^^^^^^^^^^^^^
        File "/Users/val/dev/fiddle/opt_locking/OptLocking/venv/lib/python3.11/site-packages/requests/adapters.py", line 519, in send
          raise ConnectionError(e, request=request)
      requests.exceptions.ConnectionError: HTTPConnectionPool(host='localhost', port=5656): Max retries exceeded with url: /api/auth/login (Caused by NewConnectionError('<urllib3.connection.HTTPConnection object at 0x106f97890>: Failed to establish a new connection: [Errno 61] Connection refused'))

    When Order ShippedDate altered (2013-10-13) # None
    Then Balance reduced 1086                   # None

  Scenario: Reset Shipped - adjust logic reuse  # features/place_order.feature:36
    Given Shipped Order                         # features/steps/place_order.py:337
      Traceback (most recent call last):
        File "/Users/val/dev/fiddle/opt_locking/OptLocking/venv/lib/python3.11/site-packages/urllib3/connection.py", line 174, in _new_conn
          conn = connection.create_connection(
                 ^^^^^^^^^^^^^^^^^^^^^^^^^^^^^
        File "/Users/val/dev/fiddle/opt_locking/OptLocking/venv/lib/python3.11/site-packages/urllib3/util/connection.py", line 95, in create_connection
          raise err
        File "/Users/val/dev/fiddle/opt_locking/OptLocking/venv/lib/python3.11/site-packages/urllib3/util/connection.py", line 85, in create_connection
          sock.connect(sa)
      ConnectionRefusedError: [Errno 61] Connection refused
      
      During handling of the above exception, another exception occurred:
      
      Traceback (most recent call last):
        File "/Users/val/dev/fiddle/opt_locking/OptLocking/venv/lib/python3.11/site-packages/urllib3/connectionpool.py", line 714, in urlopen
          httplib_response = self._make_request(
                             ^^^^^^^^^^^^^^^^^^^
        File "/Users/val/dev/fiddle/opt_locking/OptLocking/venv/lib/python3.11/site-packages/urllib3/connectionpool.py", line 415, in _make_request
          conn.request(method, url, **httplib_request_kw)
        File "/Users/val/dev/fiddle/opt_locking/OptLocking/venv/lib/python3.11/site-packages/urllib3/connection.py", line 244, in request
          super(HTTPConnection, self).request(method, url, body=body, headers=headers)
        File "/Library/Frameworks/Python.framework/Versions/3.11/lib/python3.11/http/client.py", line 1282, in request
          self._send_request(method, url, body, headers, encode_chunked)
        File "/Library/Frameworks/Python.framework/Versions/3.11/lib/python3.11/http/client.py", line 1328, in _send_request
          self.endheaders(body, encode_chunked=encode_chunked)
        File "/Library/Frameworks/Python.framework/Versions/3.11/lib/python3.11/http/client.py", line 1277, in endheaders
          self._send_output(message_body, encode_chunked=encode_chunked)
        File "/Library/Frameworks/Python.framework/Versions/3.11/lib/python3.11/http/client.py", line 1037, in _send_output
          self.send(msg)
        File "/Library/Frameworks/Python.framework/Versions/3.11/lib/python3.11/http/client.py", line 975, in send
          self.connect()
        File "/Users/val/dev/fiddle/opt_locking/OptLocking/venv/lib/python3.11/site-packages/urllib3/connection.py", line 205, in connect
          conn = self._new_conn()
                 ^^^^^^^^^^^^^^^^
        File "/Users/val/dev/fiddle/opt_locking/OptLocking/venv/lib/python3.11/site-packages/urllib3/connection.py", line 186, in _new_conn
          raise NewConnectionError(
      urllib3.exceptions.NewConnectionError: <urllib3.connection.HTTPConnection object at 0x106fa2910>: Failed to establish a new connection: [Errno 61] Connection refused
      
      During handling of the above exception, another exception occurred:
      
      Traceback (most recent call last):
        File "/Users/val/dev/fiddle/opt_locking/OptLocking/venv/lib/python3.11/site-packages/requests/adapters.py", line 440, in send
          resp = conn.urlopen(
                 ^^^^^^^^^^^^^
        File "/Users/val/dev/fiddle/opt_locking/OptLocking/venv/lib/python3.11/site-packages/urllib3/connectionpool.py", line 798, in urlopen
          retries = retries.increment(
                    ^^^^^^^^^^^^^^^^^^
        File "/Users/val/dev/fiddle/opt_locking/OptLocking/venv/lib/python3.11/site-packages/urllib3/util/retry.py", line 592, in increment
          raise MaxRetryError(_pool, url, error or ResponseError(cause))
      urllib3.exceptions.MaxRetryError: HTTPConnectionPool(host='localhost', port=5656): Max retries exceeded with url: /api/auth/login (Caused by NewConnectionError('<urllib3.connection.HTTPConnection object at 0x106fa2910>: Failed to establish a new connection: [Errno 61] Connection refused'))
      
      During handling of the above exception, another exception occurred:
      
      Traceback (most recent call last):
        File "/Users/val/dev/fiddle/opt_locking/OptLocking/venv/lib/python3.11/site-packages/behave/model.py", line 1329, in run
          match.run(runner.context)
        File "/Users/val/dev/fiddle/opt_locking/OptLocking/venv/lib/python3.11/site-packages/behave/matchers.py", line 98, in run
          self.func(context, *args, **kwargs)
        File "features/steps/place_order.py", line 339, in step_impl
          context.alfki_shipped = get_ALFLI()
                                  ^^^^^^^^^^^
        File "features/steps/place_order.py", line 24, in get_ALFLI
          header = test_utils.login()
                   ^^^^^^^^^^^^^^^^^^
        File "/Users/val/dev/fiddle/opt_locking/OptLocking/test/api_logic_server_behave/features/steps/test_utils.py", line 24, in login
          r = requests.post(url=post_uri, json = post_data)
              ^^^^^^^^^^^^^^^^^^^^^^^^^^^^^^^^^^^^^^^^^^^^^
        File "/Users/val/dev/fiddle/opt_locking/OptLocking/venv/lib/python3.11/site-packages/requests/api.py", line 117, in post
          return request('post', url, data=data, json=json, **kwargs)
                 ^^^^^^^^^^^^^^^^^^^^^^^^^^^^^^^^^^^^^^^^^^^^^^^^^^^^
        File "/Users/val/dev/fiddle/opt_locking/OptLocking/venv/lib/python3.11/site-packages/requests/api.py", line 61, in request
          return session.request(method=method, url=url, **kwargs)
                 ^^^^^^^^^^^^^^^^^^^^^^^^^^^^^^^^^^^^^^^^^^^^^^^^^
        File "/Users/val/dev/fiddle/opt_locking/OptLocking/venv/lib/python3.11/site-packages/requests/sessions.py", line 529, in request
          resp = self.send(prep, **send_kwargs)
                 ^^^^^^^^^^^^^^^^^^^^^^^^^^^^^^
        File "/Users/val/dev/fiddle/opt_locking/OptLocking/venv/lib/python3.11/site-packages/requests/sessions.py", line 645, in send
          r = adapter.send(request, **kwargs)
              ^^^^^^^^^^^^^^^^^^^^^^^^^^^^^^^
        File "/Users/val/dev/fiddle/opt_locking/OptLocking/venv/lib/python3.11/site-packages/requests/adapters.py", line 519, in send
          raise ConnectionError(e, request=request)
      requests.exceptions.ConnectionError: HTTPConnectionPool(host='localhost', port=5656): Max retries exceeded with url: /api/auth/login (Caused by NewConnectionError('<urllib3.connection.HTTPConnection object at 0x106fa2910>: Failed to establish a new connection: [Errno 61] Connection refused'))

    When Order ShippedDate set to None          # None
    Then Logic adjusts Balance by -1086         # None

  Scenario: Clone Existing Order              # features/place_order.feature:42
    Given Shipped Order                       # features/steps/place_order.py:337
      Traceback (most recent call last):
        File "/Users/val/dev/fiddle/opt_locking/OptLocking/venv/lib/python3.11/site-packages/urllib3/connection.py", line 174, in _new_conn
          conn = connection.create_connection(
                 ^^^^^^^^^^^^^^^^^^^^^^^^^^^^^
        File "/Users/val/dev/fiddle/opt_locking/OptLocking/venv/lib/python3.11/site-packages/urllib3/util/connection.py", line 95, in create_connection
          raise err
        File "/Users/val/dev/fiddle/opt_locking/OptLocking/venv/lib/python3.11/site-packages/urllib3/util/connection.py", line 85, in create_connection
          sock.connect(sa)
      ConnectionRefusedError: [Errno 61] Connection refused
      
      During handling of the above exception, another exception occurred:
      
      Traceback (most recent call last):
        File "/Users/val/dev/fiddle/opt_locking/OptLocking/venv/lib/python3.11/site-packages/urllib3/connectionpool.py", line 714, in urlopen
          httplib_response = self._make_request(
                             ^^^^^^^^^^^^^^^^^^^
        File "/Users/val/dev/fiddle/opt_locking/OptLocking/venv/lib/python3.11/site-packages/urllib3/connectionpool.py", line 415, in _make_request
          conn.request(method, url, **httplib_request_kw)
        File "/Users/val/dev/fiddle/opt_locking/OptLocking/venv/lib/python3.11/site-packages/urllib3/connection.py", line 244, in request
          super(HTTPConnection, self).request(method, url, body=body, headers=headers)
        File "/Library/Frameworks/Python.framework/Versions/3.11/lib/python3.11/http/client.py", line 1282, in request
          self._send_request(method, url, body, headers, encode_chunked)
        File "/Library/Frameworks/Python.framework/Versions/3.11/lib/python3.11/http/client.py", line 1328, in _send_request
          self.endheaders(body, encode_chunked=encode_chunked)
        File "/Library/Frameworks/Python.framework/Versions/3.11/lib/python3.11/http/client.py", line 1277, in endheaders
          self._send_output(message_body, encode_chunked=encode_chunked)
        File "/Library/Frameworks/Python.framework/Versions/3.11/lib/python3.11/http/client.py", line 1037, in _send_output
          self.send(msg)
        File "/Library/Frameworks/Python.framework/Versions/3.11/lib/python3.11/http/client.py", line 975, in send
          self.connect()
        File "/Users/val/dev/fiddle/opt_locking/OptLocking/venv/lib/python3.11/site-packages/urllib3/connection.py", line 205, in connect
          conn = self._new_conn()
                 ^^^^^^^^^^^^^^^^
        File "/Users/val/dev/fiddle/opt_locking/OptLocking/venv/lib/python3.11/site-packages/urllib3/connection.py", line 186, in _new_conn
          raise NewConnectionError(
      urllib3.exceptions.NewConnectionError: <urllib3.connection.HTTPConnection object at 0x106fb1710>: Failed to establish a new connection: [Errno 61] Connection refused
      
      During handling of the above exception, another exception occurred:
      
      Traceback (most recent call last):
        File "/Users/val/dev/fiddle/opt_locking/OptLocking/venv/lib/python3.11/site-packages/requests/adapters.py", line 440, in send
          resp = conn.urlopen(
                 ^^^^^^^^^^^^^
        File "/Users/val/dev/fiddle/opt_locking/OptLocking/venv/lib/python3.11/site-packages/urllib3/connectionpool.py", line 798, in urlopen
          retries = retries.increment(
                    ^^^^^^^^^^^^^^^^^^
        File "/Users/val/dev/fiddle/opt_locking/OptLocking/venv/lib/python3.11/site-packages/urllib3/util/retry.py", line 592, in increment
          raise MaxRetryError(_pool, url, error or ResponseError(cause))
      urllib3.exceptions.MaxRetryError: HTTPConnectionPool(host='localhost', port=5656): Max retries exceeded with url: /api/auth/login (Caused by NewConnectionError('<urllib3.connection.HTTPConnection object at 0x106fb1710>: Failed to establish a new connection: [Errno 61] Connection refused'))
      
      During handling of the above exception, another exception occurred:
      
      Traceback (most recent call last):
        File "/Users/val/dev/fiddle/opt_locking/OptLocking/venv/lib/python3.11/site-packages/behave/model.py", line 1329, in run
          match.run(runner.context)
        File "/Users/val/dev/fiddle/opt_locking/OptLocking/venv/lib/python3.11/site-packages/behave/matchers.py", line 98, in run
          self.func(context, *args, **kwargs)
        File "features/steps/place_order.py", line 339, in step_impl
          context.alfki_shipped = get_ALFLI()
                                  ^^^^^^^^^^^
        File "features/steps/place_order.py", line 24, in get_ALFLI
          header = test_utils.login()
                   ^^^^^^^^^^^^^^^^^^
        File "/Users/val/dev/fiddle/opt_locking/OptLocking/test/api_logic_server_behave/features/steps/test_utils.py", line 24, in login
          r = requests.post(url=post_uri, json = post_data)
              ^^^^^^^^^^^^^^^^^^^^^^^^^^^^^^^^^^^^^^^^^^^^^
        File "/Users/val/dev/fiddle/opt_locking/OptLocking/venv/lib/python3.11/site-packages/requests/api.py", line 117, in post
          return request('post', url, data=data, json=json, **kwargs)
                 ^^^^^^^^^^^^^^^^^^^^^^^^^^^^^^^^^^^^^^^^^^^^^^^^^^^^
        File "/Users/val/dev/fiddle/opt_locking/OptLocking/venv/lib/python3.11/site-packages/requests/api.py", line 61, in request
          return session.request(method=method, url=url, **kwargs)
                 ^^^^^^^^^^^^^^^^^^^^^^^^^^^^^^^^^^^^^^^^^^^^^^^^^
        File "/Users/val/dev/fiddle/opt_locking/OptLocking/venv/lib/python3.11/site-packages/requests/sessions.py", line 529, in request
          resp = self.send(prep, **send_kwargs)
                 ^^^^^^^^^^^^^^^^^^^^^^^^^^^^^^
        File "/Users/val/dev/fiddle/opt_locking/OptLocking/venv/lib/python3.11/site-packages/requests/sessions.py", line 645, in send
          r = adapter.send(request, **kwargs)
              ^^^^^^^^^^^^^^^^^^^^^^^^^^^^^^^
        File "/Users/val/dev/fiddle/opt_locking/OptLocking/venv/lib/python3.11/site-packages/requests/adapters.py", line 519, in send
          raise ConnectionError(e, request=request)
      requests.exceptions.ConnectionError: HTTPConnectionPool(host='localhost', port=5656): Max retries exceeded with url: /api/auth/login (Caused by NewConnectionError('<urllib3.connection.HTTPConnection object at 0x106fb1710>: Failed to establish a new connection: [Errno 61] Connection refused'))

    When Cloning Existing Order               # None
    Then Logic Copies ClonedFrom OrderDetails # None

Feature: Salary Change # features/salary_change.feature:1

  Scenario: Audit Salary Change              # features/salary_change.feature:3
    Given Employee 5 (Buchanan) - Salary 95k # features/steps/salary_change.py:9
    When Patch Salary to 200k                # features/steps/salary_change.py:13
      Traceback (most recent call last):
        File "/Users/val/dev/fiddle/opt_locking/OptLocking/venv/lib/python3.11/site-packages/urllib3/connection.py", line 174, in _new_conn
          conn = connection.create_connection(
                 ^^^^^^^^^^^^^^^^^^^^^^^^^^^^^
        File "/Users/val/dev/fiddle/opt_locking/OptLocking/venv/lib/python3.11/site-packages/urllib3/util/connection.py", line 95, in create_connection
          raise err
        File "/Users/val/dev/fiddle/opt_locking/OptLocking/venv/lib/python3.11/site-packages/urllib3/util/connection.py", line 85, in create_connection
          sock.connect(sa)
      ConnectionRefusedError: [Errno 61] Connection refused
      
      During handling of the above exception, another exception occurred:
      
      Traceback (most recent call last):
        File "/Users/val/dev/fiddle/opt_locking/OptLocking/venv/lib/python3.11/site-packages/urllib3/connectionpool.py", line 714, in urlopen
          httplib_response = self._make_request(
                             ^^^^^^^^^^^^^^^^^^^
        File "/Users/val/dev/fiddle/opt_locking/OptLocking/venv/lib/python3.11/site-packages/urllib3/connectionpool.py", line 415, in _make_request
          conn.request(method, url, **httplib_request_kw)
        File "/Users/val/dev/fiddle/opt_locking/OptLocking/venv/lib/python3.11/site-packages/urllib3/connection.py", line 244, in request
          super(HTTPConnection, self).request(method, url, body=body, headers=headers)
        File "/Library/Frameworks/Python.framework/Versions/3.11/lib/python3.11/http/client.py", line 1282, in request
          self._send_request(method, url, body, headers, encode_chunked)
        File "/Library/Frameworks/Python.framework/Versions/3.11/lib/python3.11/http/client.py", line 1328, in _send_request
          self.endheaders(body, encode_chunked=encode_chunked)
        File "/Library/Frameworks/Python.framework/Versions/3.11/lib/python3.11/http/client.py", line 1277, in endheaders
          self._send_output(message_body, encode_chunked=encode_chunked)
        File "/Library/Frameworks/Python.framework/Versions/3.11/lib/python3.11/http/client.py", line 1037, in _send_output
          self.send(msg)
        File "/Library/Frameworks/Python.framework/Versions/3.11/lib/python3.11/http/client.py", line 975, in send
          self.connect()
        File "/Users/val/dev/fiddle/opt_locking/OptLocking/venv/lib/python3.11/site-packages/urllib3/connection.py", line 205, in connect
          conn = self._new_conn()
                 ^^^^^^^^^^^^^^^^
        File "/Users/val/dev/fiddle/opt_locking/OptLocking/venv/lib/python3.11/site-packages/urllib3/connection.py", line 186, in _new_conn
          raise NewConnectionError(
      urllib3.exceptions.NewConnectionError: <urllib3.connection.HTTPConnection object at 0x106fb8cd0>: Failed to establish a new connection: [Errno 61] Connection refused
      
      During handling of the above exception, another exception occurred:
      
      Traceback (most recent call last):
        File "/Users/val/dev/fiddle/opt_locking/OptLocking/venv/lib/python3.11/site-packages/requests/adapters.py", line 440, in send
          resp = conn.urlopen(
                 ^^^^^^^^^^^^^
        File "/Users/val/dev/fiddle/opt_locking/OptLocking/venv/lib/python3.11/site-packages/urllib3/connectionpool.py", line 798, in urlopen
          retries = retries.increment(
                    ^^^^^^^^^^^^^^^^^^
        File "/Users/val/dev/fiddle/opt_locking/OptLocking/venv/lib/python3.11/site-packages/urllib3/util/retry.py", line 592, in increment
          raise MaxRetryError(_pool, url, error or ResponseError(cause))
      urllib3.exceptions.MaxRetryError: HTTPConnectionPool(host='localhost', port=5656): Max retries exceeded with url: /server_log?msg=%0A%0A%0AAudit%20Salary%20Change...%20alter%20salary,%20ensure%20audit%20row%20created%20(also%20available%20in%20shell%20script%0A%0A&test=Audit%20Salary%20Change&dir=test/api_logic_server_behave/logs/scenario_logic_logs (Caused by NewConnectionError('<urllib3.connection.HTTPConnection object at 0x106fb8cd0>: Failed to establish a new connection: [Errno 61] Connection refused'))
      
      During handling of the above exception, another exception occurred:
      
      Traceback (most recent call last):
        File "/Users/val/dev/fiddle/opt_locking/OptLocking/venv/lib/python3.11/site-packages/behave/model.py", line 1329, in run
          match.run(runner.context)
        File "/Users/val/dev/fiddle/opt_locking/OptLocking/venv/lib/python3.11/site-packages/behave/matchers.py", line 98, in run
          self.func(context, *args, **kwargs)
        File "features/steps/salary_change.py", line 31, in step_impl
          test_utils.prt(f'\n\n\n{scenario_name}... alter salary, ensure audit row created (also available in shell script\n\n', scenario_name)
        File "/Users/val/dev/fiddle/opt_locking/OptLocking/test/api_logic_server_behave/features/steps/test_utils.py", line 19, in prt
          r = requests.get(msg_url)
              ^^^^^^^^^^^^^^^^^^^^^
        File "/Users/val/dev/fiddle/opt_locking/OptLocking/venv/lib/python3.11/site-packages/requests/api.py", line 75, in get
          return request('get', url, params=params, **kwargs)
                 ^^^^^^^^^^^^^^^^^^^^^^^^^^^^^^^^^^^^^^^^^^^^
        File "/Users/val/dev/fiddle/opt_locking/OptLocking/venv/lib/python3.11/site-packages/requests/api.py", line 61, in request
          return session.request(method=method, url=url, **kwargs)
                 ^^^^^^^^^^^^^^^^^^^^^^^^^^^^^^^^^^^^^^^^^^^^^^^^^
        File "/Users/val/dev/fiddle/opt_locking/OptLocking/venv/lib/python3.11/site-packages/requests/sessions.py", line 529, in request
          resp = self.send(prep, **send_kwargs)
                 ^^^^^^^^^^^^^^^^^^^^^^^^^^^^^^
        File "/Users/val/dev/fiddle/opt_locking/OptLocking/venv/lib/python3.11/site-packages/requests/sessions.py", line 645, in send
          r = adapter.send(request, **kwargs)
              ^^^^^^^^^^^^^^^^^^^^^^^^^^^^^^^
        File "/Users/val/dev/fiddle/opt_locking/OptLocking/venv/lib/python3.11/site-packages/requests/adapters.py", line 519, in send
          raise ConnectionError(e, request=request)
      requests.exceptions.ConnectionError: HTTPConnectionPool(host='localhost', port=5656): Max retries exceeded with url: /server_log?msg=%0A%0A%0AAudit%20Salary%20Change...%20alter%20salary,%20ensure%20audit%20row%20created%20(also%20available%20in%20shell%20script%0A%0A&test=Audit%20Salary%20Change&dir=test/api_logic_server_behave/logs/scenario_logic_logs (Caused by NewConnectionError('<urllib3.connection.HTTPConnection object at 0x106fb8cd0>: Failed to establish a new connection: [Errno 61] Connection refused'))

    Then Salary_audit row created            # None

  Scenario: Manage ProperSalary              # features/salary_change.feature:8
    Given Employee 5 (Buchanan) - Salary 95k # features/steps/salary_change.py:9
    When Retrieve Employee Row               # features/steps/salary_change.py:106
      Traceback (most recent call last):
        File "/Users/val/dev/fiddle/opt_locking/OptLocking/venv/lib/python3.11/site-packages/urllib3/connection.py", line 174, in _new_conn
          conn = connection.create_connection(
                 ^^^^^^^^^^^^^^^^^^^^^^^^^^^^^
        File "/Users/val/dev/fiddle/opt_locking/OptLocking/venv/lib/python3.11/site-packages/urllib3/util/connection.py", line 95, in create_connection
          raise err
        File "/Users/val/dev/fiddle/opt_locking/OptLocking/venv/lib/python3.11/site-packages/urllib3/util/connection.py", line 85, in create_connection
          sock.connect(sa)
      ConnectionRefusedError: [Errno 61] Connection refused
      
      During handling of the above exception, another exception occurred:
      
      Traceback (most recent call last):
        File "/Users/val/dev/fiddle/opt_locking/OptLocking/venv/lib/python3.11/site-packages/urllib3/connectionpool.py", line 714, in urlopen
          httplib_response = self._make_request(
                             ^^^^^^^^^^^^^^^^^^^
        File "/Users/val/dev/fiddle/opt_locking/OptLocking/venv/lib/python3.11/site-packages/urllib3/connectionpool.py", line 415, in _make_request
          conn.request(method, url, **httplib_request_kw)
        File "/Users/val/dev/fiddle/opt_locking/OptLocking/venv/lib/python3.11/site-packages/urllib3/connection.py", line 244, in request
          super(HTTPConnection, self).request(method, url, body=body, headers=headers)
        File "/Library/Frameworks/Python.framework/Versions/3.11/lib/python3.11/http/client.py", line 1282, in request
          self._send_request(method, url, body, headers, encode_chunked)
        File "/Library/Frameworks/Python.framework/Versions/3.11/lib/python3.11/http/client.py", line 1328, in _send_request
          self.endheaders(body, encode_chunked=encode_chunked)
        File "/Library/Frameworks/Python.framework/Versions/3.11/lib/python3.11/http/client.py", line 1277, in endheaders
          self._send_output(message_body, encode_chunked=encode_chunked)
        File "/Library/Frameworks/Python.framework/Versions/3.11/lib/python3.11/http/client.py", line 1037, in _send_output
          self.send(msg)
        File "/Library/Frameworks/Python.framework/Versions/3.11/lib/python3.11/http/client.py", line 975, in send
          self.connect()
        File "/Users/val/dev/fiddle/opt_locking/OptLocking/venv/lib/python3.11/site-packages/urllib3/connection.py", line 205, in connect
          conn = self._new_conn()
                 ^^^^^^^^^^^^^^^^
        File "/Users/val/dev/fiddle/opt_locking/OptLocking/venv/lib/python3.11/site-packages/urllib3/connection.py", line 186, in _new_conn
          raise NewConnectionError(
      urllib3.exceptions.NewConnectionError: <urllib3.connection.HTTPConnection object at 0x104daec50>: Failed to establish a new connection: [Errno 61] Connection refused
      
      During handling of the above exception, another exception occurred:
      
      Traceback (most recent call last):
        File "/Users/val/dev/fiddle/opt_locking/OptLocking/venv/lib/python3.11/site-packages/requests/adapters.py", line 440, in send
          resp = conn.urlopen(
                 ^^^^^^^^^^^^^
        File "/Users/val/dev/fiddle/opt_locking/OptLocking/venv/lib/python3.11/site-packages/urllib3/connectionpool.py", line 798, in urlopen
          retries = retries.increment(
                    ^^^^^^^^^^^^^^^^^^
        File "/Users/val/dev/fiddle/opt_locking/OptLocking/venv/lib/python3.11/site-packages/urllib3/util/retry.py", line 592, in increment
          raise MaxRetryError(_pool, url, error or ResponseError(cause))
      urllib3.exceptions.MaxRetryError: HTTPConnectionPool(host='localhost', port=5656): Max retries exceeded with url: /server_log?msg=%0A%0A%0AManage%20ProperSalary...%20Get%20Employee%20-%20verify%20contains%20virtual%20ProperSalary%0A%0A&test=Manage%20ProperSalary&dir=test/api_logic_server_behave/logs/scenario_logic_logs (Caused by NewConnectionError('<urllib3.connection.HTTPConnection object at 0x104daec50>: Failed to establish a new connection: [Errno 61] Connection refused'))
      
      During handling of the above exception, another exception occurred:
      
      Traceback (most recent call last):
        File "/Users/val/dev/fiddle/opt_locking/OptLocking/venv/lib/python3.11/site-packages/behave/model.py", line 1329, in run
          match.run(runner.context)
        File "/Users/val/dev/fiddle/opt_locking/OptLocking/venv/lib/python3.11/site-packages/behave/matchers.py", line 98, in run
          self.func(context, *args, **kwargs)
        File "features/steps/salary_change.py", line 115, in step_impl
          test_utils.prt(f'\n\n\n{scenario_name}... Get Employee - verify contains virtual ProperSalary\n\n', scenario_name)
        File "/Users/val/dev/fiddle/opt_locking/OptLocking/test/api_logic_server_behave/features/steps/test_utils.py", line 19, in prt
          r = requests.get(msg_url)
              ^^^^^^^^^^^^^^^^^^^^^
        File "/Users/val/dev/fiddle/opt_locking/OptLocking/venv/lib/python3.11/site-packages/requests/api.py", line 75, in get
          return request('get', url, params=params, **kwargs)
                 ^^^^^^^^^^^^^^^^^^^^^^^^^^^^^^^^^^^^^^^^^^^^
        File "/Users/val/dev/fiddle/opt_locking/OptLocking/venv/lib/python3.11/site-packages/requests/api.py", line 61, in request
          return session.request(method=method, url=url, **kwargs)
                 ^^^^^^^^^^^^^^^^^^^^^^^^^^^^^^^^^^^^^^^^^^^^^^^^^
        File "/Users/val/dev/fiddle/opt_locking/OptLocking/venv/lib/python3.11/site-packages/requests/sessions.py", line 529, in request
          resp = self.send(prep, **send_kwargs)
                 ^^^^^^^^^^^^^^^^^^^^^^^^^^^^^^
        File "/Users/val/dev/fiddle/opt_locking/OptLocking/venv/lib/python3.11/site-packages/requests/sessions.py", line 645, in send
          r = adapter.send(request, **kwargs)
              ^^^^^^^^^^^^^^^^^^^^^^^^^^^^^^^
        File "/Users/val/dev/fiddle/opt_locking/OptLocking/venv/lib/python3.11/site-packages/requests/adapters.py", line 519, in send
          raise ConnectionError(e, request=request)
      requests.exceptions.ConnectionError: HTTPConnectionPool(host='localhost', port=5656): Max retries exceeded with url: /server_log?msg=%0A%0A%0AManage%20ProperSalary...%20Get%20Employee%20-%20verify%20contains%20virtual%20ProperSalary%0A%0A&test=Manage%20ProperSalary&dir=test/api_logic_server_behave/logs/scenario_logic_logs (Caused by NewConnectionError('<urllib3.connection.HTTPConnection object at 0x104daec50>: Failed to establish a new connection: [Errno 61] Connection refused'))

    Then Verify Contains ProperSalary        # None

  Scenario: Raise Must be Meaningful         # features/salary_change.feature:13
    Given Employee 5 (Buchanan) - Salary 95k # features/steps/salary_change.py:9
    When Patch Salary to 96k                 # features/steps/salary_change.py:76
      Traceback (most recent call last):
        File "/Users/val/dev/fiddle/opt_locking/OptLocking/venv/lib/python3.11/site-packages/urllib3/connection.py", line 174, in _new_conn
          conn = connection.create_connection(
                 ^^^^^^^^^^^^^^^^^^^^^^^^^^^^^
        File "/Users/val/dev/fiddle/opt_locking/OptLocking/venv/lib/python3.11/site-packages/urllib3/util/connection.py", line 95, in create_connection
          raise err
        File "/Users/val/dev/fiddle/opt_locking/OptLocking/venv/lib/python3.11/site-packages/urllib3/util/connection.py", line 85, in create_connection
          sock.connect(sa)
      ConnectionRefusedError: [Errno 61] Connection refused
      
      During handling of the above exception, another exception occurred:
      
      Traceback (most recent call last):
        File "/Users/val/dev/fiddle/opt_locking/OptLocking/venv/lib/python3.11/site-packages/urllib3/connectionpool.py", line 714, in urlopen
          httplib_response = self._make_request(
                             ^^^^^^^^^^^^^^^^^^^
        File "/Users/val/dev/fiddle/opt_locking/OptLocking/venv/lib/python3.11/site-packages/urllib3/connectionpool.py", line 415, in _make_request
          conn.request(method, url, **httplib_request_kw)
        File "/Users/val/dev/fiddle/opt_locking/OptLocking/venv/lib/python3.11/site-packages/urllib3/connection.py", line 244, in request
          super(HTTPConnection, self).request(method, url, body=body, headers=headers)
        File "/Library/Frameworks/Python.framework/Versions/3.11/lib/python3.11/http/client.py", line 1282, in request
          self._send_request(method, url, body, headers, encode_chunked)
        File "/Library/Frameworks/Python.framework/Versions/3.11/lib/python3.11/http/client.py", line 1328, in _send_request
          self.endheaders(body, encode_chunked=encode_chunked)
        File "/Library/Frameworks/Python.framework/Versions/3.11/lib/python3.11/http/client.py", line 1277, in endheaders
          self._send_output(message_body, encode_chunked=encode_chunked)
        File "/Library/Frameworks/Python.framework/Versions/3.11/lib/python3.11/http/client.py", line 1037, in _send_output
          self.send(msg)
        File "/Library/Frameworks/Python.framework/Versions/3.11/lib/python3.11/http/client.py", line 975, in send
          self.connect()
        File "/Users/val/dev/fiddle/opt_locking/OptLocking/venv/lib/python3.11/site-packages/urllib3/connection.py", line 205, in connect
          conn = self._new_conn()
                 ^^^^^^^^^^^^^^^^
        File "/Users/val/dev/fiddle/opt_locking/OptLocking/venv/lib/python3.11/site-packages/urllib3/connection.py", line 186, in _new_conn
          raise NewConnectionError(
      urllib3.exceptions.NewConnectionError: <urllib3.connection.HTTPConnection object at 0x106fba0d0>: Failed to establish a new connection: [Errno 61] Connection refused
      
      During handling of the above exception, another exception occurred:
      
      Traceback (most recent call last):
        File "/Users/val/dev/fiddle/opt_locking/OptLocking/venv/lib/python3.11/site-packages/requests/adapters.py", line 440, in send
          resp = conn.urlopen(
                 ^^^^^^^^^^^^^
        File "/Users/val/dev/fiddle/opt_locking/OptLocking/venv/lib/python3.11/site-packages/urllib3/connectionpool.py", line 798, in urlopen
          retries = retries.increment(
                    ^^^^^^^^^^^^^^^^^^
        File "/Users/val/dev/fiddle/opt_locking/OptLocking/venv/lib/python3.11/site-packages/urllib3/util/retry.py", line 592, in increment
          raise MaxRetryError(_pool, url, error or ResponseError(cause))
      urllib3.exceptions.MaxRetryError: HTTPConnectionPool(host='localhost', port=5656): Max retries exceeded with url: /server_log?msg=%0A%0A%0ARaise%20Must%20be%20Meaningful...%20alter%20salary,%20ensure%20audit%20row%20created%20(also%20available%20in%20shell%20script%0A%0A&test=Raise%20Must%20be%20Meaningful&dir=test/api_logic_server_behave/logs/scenario_logic_logs (Caused by NewConnectionError('<urllib3.connection.HTTPConnection object at 0x106fba0d0>: Failed to establish a new connection: [Errno 61] Connection refused'))
      
      During handling of the above exception, another exception occurred:
      
      Traceback (most recent call last):
        File "/Users/val/dev/fiddle/opt_locking/OptLocking/venv/lib/python3.11/site-packages/behave/model.py", line 1329, in run
          match.run(runner.context)
        File "/Users/val/dev/fiddle/opt_locking/OptLocking/venv/lib/python3.11/site-packages/behave/matchers.py", line 98, in run
          self.func(context, *args, **kwargs)
        File "features/steps/salary_change.py", line 85, in step_impl
          test_utils.prt(f'\n\n\n{scenario_name}... alter salary, ensure audit row created (also available in shell script\n\n', scenario_name)
        File "/Users/val/dev/fiddle/opt_locking/OptLocking/test/api_logic_server_behave/features/steps/test_utils.py", line 19, in prt
          r = requests.get(msg_url)
              ^^^^^^^^^^^^^^^^^^^^^
        File "/Users/val/dev/fiddle/opt_locking/OptLocking/venv/lib/python3.11/site-packages/requests/api.py", line 75, in get
          return request('get', url, params=params, **kwargs)
                 ^^^^^^^^^^^^^^^^^^^^^^^^^^^^^^^^^^^^^^^^^^^^
        File "/Users/val/dev/fiddle/opt_locking/OptLocking/venv/lib/python3.11/site-packages/requests/api.py", line 61, in request
          return session.request(method=method, url=url, **kwargs)
                 ^^^^^^^^^^^^^^^^^^^^^^^^^^^^^^^^^^^^^^^^^^^^^^^^^
        File "/Users/val/dev/fiddle/opt_locking/OptLocking/venv/lib/python3.11/site-packages/requests/sessions.py", line 529, in request
          resp = self.send(prep, **send_kwargs)
                 ^^^^^^^^^^^^^^^^^^^^^^^^^^^^^^
        File "/Users/val/dev/fiddle/opt_locking/OptLocking/venv/lib/python3.11/site-packages/requests/sessions.py", line 645, in send
          r = adapter.send(request, **kwargs)
              ^^^^^^^^^^^^^^^^^^^^^^^^^^^^^^^
        File "/Users/val/dev/fiddle/opt_locking/OptLocking/venv/lib/python3.11/site-packages/requests/adapters.py", line 519, in send
          raise ConnectionError(e, request=request)
      requests.exceptions.ConnectionError: HTTPConnectionPool(host='localhost', port=5656): Max retries exceeded with url: /server_log?msg=%0A%0A%0ARaise%20Must%20be%20Meaningful...%20alter%20salary,%20ensure%20audit%20row%20created%20(also%20available%20in%20shell%20script%0A%0A&test=Raise%20Must%20be%20Meaningful&dir=test/api_logic_server_behave/logs/scenario_logic_logs (Caused by NewConnectionError('<urllib3.connection.HTTPConnection object at 0x106fba0d0>: Failed to establish a new connection: [Errno 61] Connection refused'))

    Then Reject - Raise too small            # None

&nbsp;&nbsp;
Completed at May 28, 2023 10:23:14